Workbook
Name BUDGET: LP_Model!$B$2
Name FICO_MIN: LP_Model!$B$3
Name DTI_MAX: LP_Model!$B$4
Name x_vars: LP_Model!$J$6:$J$65
Name OBJ: LP_Model!$B$68

Sheet Data
A1: Region | B1: Proposito | C1: FICO_mid | D1: APR | E1: PD | F1: LGD | G1: DTI | H1: RAR | I1: EAD_cap | J1: x_alloc | K1: EL | L1: Expected_Return | M1: RAR_Value
A2: Andina | B2: Deuda | C2: 680 | D2: 0.2120862 | E2: 0.0841495 | F2: 0.55712457 | G2: 0.41761515 | H2: 0.16520445 | I2: 5000000 | J2: 0 | K2: 0 | L2: 0 | M2: 0
A3: Andina | B3: Deuda | C3: 720 | D3: 0.20901656 | E3: 0.061316261 | F3: 0.56737134 | G3: 0.37383717 | H3: 0.17422747 | I3: 5000000 | J3: 0 | K3: 0 | L3: 0 | M3: 0
A4: Andina | B4: Deuda | C4: 770 | D4: 0.20802821 | E4: 0.046240594 | F4: 0.54490241 | G4: 0.34767135 | H4: 0.1828316 | I4: 5000000 | J4: 5000000 | K4: 125983.06 | L4: 1040141 | M4: 914157.98
A5: Andina | B5: Negocio | C5: 680 | D5: 0.24116142 | E5: 0.091903655 | F5: 0.57930099 | G5: 0.38718856 | H5: 0.18792154 | I5: 5000000 | J5: 0 | K5: 0 | L5: 0 | M5: 0
A6: Andina | B6: Negocio | C6: 720 | D6: 0.23513841 | E6: 0.071921704 | F6: 0.58910371 | G6: 0.34293848 | H6: 0.19276907 | I6: 5000000 | J6: 5000000 | K6: 211846.71 | L6: 1175692.1 | M6: 963845.34
A7: Andina | B7: Negocio | C7: 770 | D7: 0.24703511 | E7: 0.052144402 | F7: 0.60081034 | G7: 0.32287626 | H7: 0.21570622 | I7: 5000000 | J7: 5000000 | K7: 156644.48 | L7: 1235175.6 | M7: 1078531.1
A8: Andina | B8: Vivienda | C8: 680 | D8: 0.15825798 | E8: 0.045651409 | F8: 0.29309404 | G8: 0.33187849 | H8: 0.14487782 | I8: 5000000 | J8: 0 | K8: 0 | L8: 0 | M8: 0
A9: Andina | B9: Vivienda | C9: 720 | D9: 0.15807796 | E9: 0.032959035 | F9: 0.29638976 | G9: 0.29926139 | H9: 0.14830924 | I9: 5000000 | J9: 0 | K9: 0 | L9: 0 | M9: 0
A10: Andina | B10: Vivienda | C10: 770 | D10: 0.15995681 | E10: 0.023722582 | F10: 0.30493527 | G10: 0.26389578 | H10: 0.15272296 | I10: 5000000 | J10: 5000000 | K10: 36169.26 | L10: 799784.04 | M10: 763614.78
A11: Andina | B11: Educación | C11: 680 | D11: 0.18075191 | E11: 0.055060779 | F11: 0.38937451 | G11: 0.37098431 | H11: 0.15931265 | I11: 5000000 | J11: 0 | K11: 0 | L11: 0 | M11: 0
A12: Andina | B12: Educación | C12: 720 | D12: 0.18265848 | E12: 0.04296978 | F12: 0.39907481 | G12: 0.32849448 | H12: 0.16551032 | I12: 5000000 | J12: 5000000 | K12: 85740.784 | L12: 913292.4 | M12: 827551.61
A13: Andina | B13: Educación | C13: 770 | D13: 0.17467732 | E13: 0.030819747 | F13: 0.39631489 | G13: 0.31528561 | H13: 0.162463 | I13: 5000000 | J13: 5000000 | K13: 61071.624 | L13: 873386.6 | M13: 812314.98
... A61: Amazonía | B61: Educación | C61: 770 | D61: 0.17789077 | E61: 0.034843819 | F61: 0.39470571 | G61: 0.31426217 | H61: 0.16413772 | I61: 5000000 | J61: 0 | K61: 0 | L61: 0 | M61: 0

Sheet LP_Model
A1: Parámetro | B1: Valor | C1: Notas
A2: BUDGET | B2: 100000000 | C2: Presupuesto total de colocación (celda nombrada)
A3: FICO_MIN | B3: 700 | C3: Umbral mínimo promedio de FICO (restricción lineal)
A4: DTI_MAX | B4: 0.35 | C4: Umbral máximo promedio de DTI (restricción lineal)
A5: Nombre | B5: Región | C5: Propósito | D5: FICO_mid | E5: APR | F5: PD | G5: LGD | H5: DTI | I5: EAD_cap | J5: x_vars | K5: RAR_per_unit | L5: EL_per_unit
A6: seg_01 | B6: =INDEX(Data!A:A,2) | C6: =INDEX(Data!B:B,2) | D6: =INDEX(Data!C:C,2) | E6: =INDEX(Data!D:D,2) | F6: =INDEX(Data!E:E,2) | G6: =INDEX(Data!F:F,2) | H6: =INDEX(Data!G:G,2) | I6: =INDEX(Data!H:H,2)*0+5000000.0 | J6: 0 | K6: =E6-F6*G6 | L6: =F6*G6
A7: seg_02 | B7: =INDEX(Data!A:A,3) | C7: =INDEX(Data!B:B,3) | D7: =INDEX(Data!C:C,3) | E7: =INDEX(Data!D:D,3) | F7: =INDEX(Data!E:E,3) | G7: =INDEX(Data!F:F,3) | H7: =INDEX(Data!G:G,3) | I7: =INDEX(Data!H:H,3)*0+5000000.0 | J7: 0 | K7: =E7-F7*G7 | L7: =F7*G7
A8: seg_03 | B8: =INDEX(Data!A:A,4) | C8: =INDEX(Data!B:B,4) | D8: =INDEX(Data!C:C,4) | E8: =INDEX(Data!D:D,4) | F8: =INDEX(Data!E:E,4) | G8: =INDEX(Data!F:F,4) | H8: =INDEX(Data!G:G,4) | I8: =INDEX(Data!H:H,4)*0+5000000.0 | J8: 5000000 | K8: =E8-F8*G8 | L8: =F8*G8
A9: seg_04 | B9: =INDEX(Data!A:A,5) | C9: =INDEX(Data!B:B,5) | D9: =INDEX(Data!C:C,5) | E9: =INDEX(Data!D:D,5) | F9: =INDEX(Data!E:E,5) | G9: =INDEX(Data!F:F,5) | H9: =INDEX(Data!G:G,5) | I9: =INDEX(Data!H:H,5)*0+5000000.0 | J9: 0 | K9: =E9-F9*G9 | L9: =F9*G9
A10: seg_05 | B10: =INDEX(Data!A:A,6) | C10: =INDEX(Data!B:B,6) | D10: =INDEX(Data!C:C,6) | E10: =INDEX(Data!D:D,6) | F10: =INDEX(Data!E:E,6) | G10: =INDEX(Data!F:F,6) | H10: =INDEX(Data!G:G,6) | I10: =INDEX(Data!H:H,6)*0+5000000.0 | J10: 5000000 | K10: =E10-F10*G10 | L10: =F10*G10
A11: seg_06 | B11: =INDEX(Data!A:A,7) | C11: =INDEX(Data!B:B,7) | D11: =INDEX(Data!C:C,7) | E11: =INDEX(Data!D:D,7) | F11: =INDEX(Data!E:E,7) | G11: =INDEX(Data!F:F,7) | H11: =INDEX(Data!G:G,7) | I11: =INDEX(Data!H:H,7)*0+5000000.0 | J11: 5000000 | K11: =E11-F11*G11 | L11: =F11*G11
A12: seg_07 | B12: =INDEX(Data!A:A,8) | C12: =INDEX(Data!B:B,8) | D12: =INDEX(Data!C:C,8) | E12: =INDEX(Data!D:D,8) | F12: =INDEX(Data!E:E,8) | G12: =INDEX(Data!F:F,8) | H12: =INDEX(Data!G:G,8) | I12: =INDEX(Data!H:H,8)*0+5000000.0 | J12: 0 | K12: =E12-F12*G12 | L12: =F12*G12
A13: seg_08 | B13: =INDEX(Data!A:A,9) | C13: =INDEX(Data!B:B,9) | D13: =INDEX(Data!C:C,9) | E13: =INDEX(Data!D:D,9) | F13: =INDEX(Data!E:E,9) | G13: =INDEX(Data!F:F,9) | H13: =INDEX(Data!G:G,9) | I13: =INDEX(Data!H:H,9)*0+5000000.0 | J13: 0 | K13: =E13-F13*G13 | L13: =F13*G13
A14: seg_09 | B14: =INDEX(Data!A:A,10) | C14: =INDEX(Data!B:B,10) | D14: =INDEX(Data!C:C,10) | E14: =INDEX(Data!D:D,10) | F14: =INDEX(Data!E:E,10) | G14: =INDEX(Data!F:F,10) | H14: =INDEX(Data!G:G,10) | I14: =INDEX(Data!H:H,10)*0+5000000.0 | J14: 5000000 | K14: =E14-F14*G14 | L14: =F14*G14
A15: seg_10 | B15: =INDEX(Data!A:A,11) | C15: =INDEX(Data!B:B,11) | D15: =INDEX(Data!C:C,11) | E15: =INDEX(Data!D:D,11) | F15: =INDEX(Data!E:E,11) | G15: =INDEX(Data!F:F,11) | H15: =INDEX(Data!G:G,11) | I15: =INDEX(Data!H:H,11)*0+5000000.0 | J15: 0 | K15: =E15-F15*G15 | L15: =F15*G15
A16: seg_11 | B16: =INDEX(Data!A:A,12) | C16: =INDEX(Data!B:B,12) | D16: =INDEX(Data!C:C,12) | E16: =INDEX(Data!D:D,12) | F16: =INDEX(Data!E:E,12) | G16: =INDEX(Data!F:F,12) | H16: =INDEX(Data!G:G,12) | I16: =INDEX(Data!H:H,12)*0+5000000.0 | J16: 5000000 | K16: =E16-F16*G16 | L16: =F16*G16
A17: seg_12 | B17: =INDEX(Data!A:A,13) | C17: =INDEX(Data!B:B,13) | D17: =INDEX(Data!C:C,13) | E17: =INDEX(Data!D:D,13) | F17: =INDEX(Data!E:E,13) | G17: =INDEX(Data!F:F,13) | H17: =INDEX(Data!G:G,13) | I17: =INDEX(Data!H:H,13)*0+5000000.0 | J17: 5000000 | K17: =E17-F17*G17 | L17: =F17*G17
A18: seg_13 | B18: =INDEX(Data!A:A,14) | C18: =INDEX(Data!B:B,14) | D18: =INDEX(Data!C:C,14) | E18: =INDEX(Data!D:D,14) | F18: =INDEX(Data!E:E,14) | G18: =INDEX(Data!F:F,14) | H18: =INDEX(Data!G:G,14) | I18: =INDEX(Data!H:H,14)*0+5000000.0 | J18: 0 | K18: =E18-F18*G18 | L18: =F18*G18
A19: seg_14 | B19: =INDEX(Data!A:A,15) | C19: =INDEX(Data!B:B,15) | D19: =INDEX(Data!C:C,15) | E19: =INDEX(Data!D:D,15) | F19: =INDEX(Data!E:E,15) | G19: =INDEX(Data!F:F,15) | H19: =INDEX(Data!G:G,15) | I19: =INDEX(Data!H:H,15)*0+5000000.0 | J19: 0 | K19: =E19-F19*G19 | L19: =F19*G19
A20: seg_15 | B20: =INDEX(Data!A:A,16) | C20: =INDEX(Data!B:B,16) | D20: =INDEX(Data!C:C,16) | E20: =INDEX(Data!D:D,16) | F20: =INDEX(Data!E:E,16) | G20: =INDEX(Data!F:F,16) | H20: =INDEX(Data!G:G,16) | I20: =INDEX(Data!H:H,16)*0+5000000.0 | J20: 0 | K20: =E20-F20*G20 | L20: =F20*G20
A21: seg_16 | B21: =INDEX(Data!A:A,17) | C21: =INDEX(Data!B:B,17) | D21: =INDEX(Data!C:C,17) | E21: =INDEX(Data!D:D,17) | F21: =INDEX(Data!E:E,17) | G21: =INDEX(Data!F:F,17) | H21: =INDEX(Data!G:G,17) | I21: =INDEX(Data!H:H,17)*0+5000000.0 | J21: 0 | K21: =E21-F21*G21 | L21: =F21*G21
A22: seg_17 | B22: =INDEX(Data!A:A,18) | C22: =INDEX(Data!B:B,18) | D22: =INDEX(Data!C:C,18) | E22: =INDEX(Data!D:D,18) | F22: =INDEX(Data!E:E,18) | G22: =INDEX(Data!F:F,18) | H22: =INDEX(Data!G:G,18) | I22: =INDEX(Data!H:H,18)*0+5000000.0 | J22: 0 | K22: =E22-F22*G22 | L22: =F22*G22
A23: seg_18 | B23: =INDEX(Data!A:A,19) | C23: =INDEX(Data!B:B,19) | D23: =INDEX(Data!C:C,19) | E23: =INDEX(Data!D:D,19) | F23: =INDEX(Data!E:E,19) | G23: =INDEX(Data!F:F,19) | H23: =INDEX(Data!G:G,19) | I23: =INDEX(Data!H:H,19)*0+5000000.0 | J23: 5000000 | K23: =E23-F23*G23 | L23: =F23*G23
A24: seg_19 | B24: =INDEX(Data!A:A,20) | C24: =INDEX(Data!B:B,20) | D24: =INDEX(Data!C:C,20) | E24: =INDEX(Data!D:D,20) | F24: =INDEX(Data!E:E,20) | G24: =INDEX(Data!F:F,20) | H24: =INDEX(Data!G:G,20) | I24: =INDEX(Data!H:H,20)*0+5000000.0 | J24: 0 | K24: =E24-F24*G24 | L24: =F24*G24
A25: seg_20 | B25: =INDEX(Data!A:A,21) | C25: =INDEX(Data!B:B,21) | D25: =INDEX(Data!C:C,21) | E25: =INDEX(Data!D:D,21) | F25: =INDEX(Data!E:E,21) | G25: =INDEX(Data!F:F,21) | H25: =INDEX(Data!G:G,21) | I25: =INDEX(Data!H:H,21)*0+5000000.0 | J25: 5000000 | K25: =E25-F25*G25 | L25: =F25*G25
A26: seg_21 | B26: =INDEX(Data!A:A,22) | C26: =INDEX(Data!B:B,22) | D26: =INDEX(Data!C:C,22) | E26: =INDEX(Data!D:D,22) | F26: =INDEX(Data!E:E,22) | G26: =INDEX(Data!F:F,22) | H26: =INDEX(Data!G:G,22) | I26: =INDEX(Data!H:H,22)*0+5000000.0 | J26: 5000000 | K26: =E26-F26*G26 | L26: =F26*G26
A27: seg_22 | B27: =INDEX(Data!A:A,23) | C27: =INDEX(Data!B:B,23) | D27: =INDEX(Data!C:C,23) | E27: =INDEX(Data!D:D,23) | F27: =INDEX(Data!E:E,23) | G27: =INDEX(Data!F:F,23) | H27: =INDEX(Data!G:G,23) | I27: =INDEX(Data!H:H,23)*0+5000000.0 | J27: 0 | K27: =E27-F27*G27 | L27: =F27*G27
A28: seg_23 | B28: =INDEX(Data!A:A,24) | C28: =INDEX(Data!B:B,24) | D28: =INDEX(Data!C:C,24) | E28: =INDEX(Data!D:D,24) | F28: =INDEX(Data!E:E,24) | G28: =INDEX(Data!F:F,24) | H28: =INDEX(Data!G:G,24) | I28: =INDEX(Data!H:H,24)*0+5000000.0 | J28: 5000000 | K28: =E28-F28*G28 | L28: =F28*G28
A29: seg_24 | B29: =INDEX(Data!A:A,25) | C29: =INDEX(Data!B:B,25) | D29: =INDEX(Data!C:C,25) | E29: =INDEX(Data!D:D,25) | F29: =INDEX(Data!E:E,25) | G29: =INDEX(Data!F:F,25) | H29: =INDEX(Data!G:G,25) | I29: =INDEX(Data!H:H,25)*0+5000000.0 | J29: 5000000 | K29: =E29-F29*G29 | L29: =F29*G29
A30: seg_25 | B30: =INDEX(Data!A:A,26) | C30: =INDEX(Data!B:B,26) | D30: =INDEX(Data!C:C,26) | E30: =INDEX(Data!D:D,26) | F30: =INDEX(Data!E:E,26) | G30: =INDEX(Data!F:F,26) | H30: =INDEX(Data!G:G,26) | I30: =INDEX(Data!H:H,26)*0+5000000.0 | J30: 0 | K30: =E30-F30*G30 | L30: =F30*G30
A31: seg_26 | B31: =INDEX(Data!A:A,27) | C31: =INDEX(Data!B:B,27) | D31: =INDEX(Data!C:C,27) | E31: =INDEX(Data!D:D,27) | F31: =INDEX(Data!E:E,27) | G31: =INDEX(Data!F:F,27) | H31: =INDEX(Data!G:G,27) | I31: =INDEX(Data!H:H,27)*0+5000000.0 | J31: 0 | K31: =E31-F31*G31 | L31: =F31*G31
A32: seg_27 | B32: =INDEX(Data!A:A,28) | C32: =INDEX(Data!B:B,28) | D32: =INDEX(Data!C:C,28) | E32: =INDEX(Data!D:D,28) | F32: =INDEX(Data!E:E,28) | G32: =INDEX(Data!F:F,28) | H32: =INDEX(Data!G:G,28) | I32: =INDEX(Data!H:H,28)*0+5000000.0 | J32: 0 | K32: =E32-F32*G32 | L32: =F32*G32
A33: seg_28 | B33: =INDEX(Data!A:A,29) | C33: =INDEX(Data!B:B,29) | D33: =INDEX(Data!C:C,29) | E33: =INDEX(Data!D:D,29) | F33: =INDEX(Data!E:E,29) | G33: =INDEX(Data!F:F,29) | H33: =INDEX(Data!G:G,29) | I33: =INDEX(Data!H:H,29)*0+5000000.0 | J33: 0 | K33: =E33-F33*G33 | L33: =F33*G33
A34: seg_29 | B34: =INDEX(Data!A:A,30) | C34: =INDEX(Data!B:B,30) | D34: =INDEX(Data!C:C,30) | E34: =INDEX(Data!D:D,30) | F34: =INDEX(Data!E:E,30) | G34: =INDEX(Data!F:F,30) | H34: =INDEX(Data!G:G,30) | I34: =INDEX(Data!H:H,30)*0+5000000.0 | J34: 0 | K34: =E34-F34*G34 | L34: =F34*G34
A35: seg_30 | B35: =INDEX(Data!A:A,31) | C35: =INDEX(Data!B:B,31) | D35: =INDEX(Data!C:C,31) | E35: =INDEX(Data!D:D,31) | F35: =INDEX(Data!E:E,31) | G35: =INDEX(Data!F:F,31) | H35: =INDEX(Data!G:G,31) | I35: =INDEX(Data!H:H,31)*0+5000000.0 | J35: 5000000 | K35: =E35-F35*G35 | L35: =F35*G35
A36: seg_31 | B36: =INDEX(Data!A:A,32) | C36: =INDEX(Data!B:B,32) | D36: =INDEX(Data!C:C,32) | E36: =INDEX(Data!D:D,32) | F36: =INDEX(Data!E:E,32) | G36: =INDEX(Data!F:F,32) | H36: =INDEX(Data!G:G,32) | I36: =INDEX(Data!H:H,32)*0+5000000.0 | J36: 0 | K36: =E36-F36*G36 | L36: =F36*G36
A37: seg_32 | B37: =INDEX(Data!A:A,33) | C37: =INDEX(Data!B:B,33) | D37: =INDEX(Data!C:C,33) | E37: =INDEX(Data!D:D,33) | F37: =INDEX(Data!E:E,33) | G37: =INDEX(Data!F:F,33) | H37: =INDEX(Data!G:G,33) | I37: =INDEX(Data!H:H,33)*0+5000000.0 | J37: 0 | K37: =E37-F37*G37 | L37: =F37*G37
A38: seg_33 | B38: =INDEX(Data!A:A,34) | C38: =INDEX(Data!B:B,34) | D38: =INDEX(Data!C:C,34) | E38: =INDEX(Data!D:D,34) | F38: =INDEX(Data!E:E,34) | G38: =INDEX(Data!F:F,34) | H38: =INDEX(Data!G:G,34) | I38: =INDEX(Data!H:H,34)*0+5000000.0 | J38: 0 | K38: =E38-F38*G38 | L38: =F38*G38
A39: seg_34 | B39: =INDEX(Data!A:A,35) | C39: =INDEX(Data!B:B,35) | D39: =INDEX(Data!C:C,35) | E39: =INDEX(Data!D:D,35) | F39: =INDEX(Data!E:E,35) | G39: =INDEX(Data!F:F,35) | H39: =INDEX(Data!G:G,35) | I39: =INDEX(Data!H:H,35)*0+5000000.0 | J39: 0 | K39: =E39-F39*G39 | L39: =F39*G39
A40: seg_35 | B40: =INDEX(Data!A:A,36) | C40: =INDEX(Data!B:B,36) | D40: =INDEX(Data!C:C,36) | E40: =INDEX(Data!D:D,36) | F40: =INDEX(Data!E:E,36) | G40: =INDEX(Data!F:F,36) | H40: =INDEX(Data!G:G,36) | I40: =INDEX(Data!H:H,36)*0+5000000.0 | J40: 0 | K40: =E40-F40*G40 | L40: =F40*G40
...

Sheet Instrucciones
A1: APORTE 1 – Modelo PL (Excel Solver) – Axia Data
A2: 1) Hoja 'LP_Model':
A3: - B2 = BUDGET (cambiante).
A4: - Defina la celda objetivo: LP_Model!B68 (maximizar OBJ_RAR).
A5: - Celdas cambiantes: rango J6:J65 (x_vars).
A6: - Restricciones:
A7: a) Total_Asignado (B69) = BUDGET (B2).
A8: b) Avg_FICO (B72) >= FICO_MIN (B3).
A9: c) Avg_DTI (B73) <= DTI_MAX (B4).
A10: d) Para cada región en bloque 'Control de límites': Asignado <= Límite.
A11: e) Para cada propósito: Asignado entre [Mín, Máx].
A12: f) No negatividad: x_vars >= 0 y x_vars <= EAD_cap (columna I).
... A16: 5) 'Binary_Model' contiene el modelo de crisis (0/1) para priorización de medidas.

Sheet Sensitivity
A1: Parámetro | B1: Base | C1: -20% | D1: -10% | E1: -5% | F1: +5% | G1: +10% | H1: +20% | I1: Nota
A2: APR (global multiplicador) | B2: 1 | C2: 0.8 | D2: 0.9 | E2: 0.95 | F2: 1.05 | G2: 1.1 | H2: 1.2 | I2: Multiplica Data!APR
A3: PD (global multiplicador) | B3: 1 | C3: 0.8 | D3: 0.9 | E3: 0.95 | F3: 1.05 | G3: 1.1 | H3: 1.2 | I3: Multiplica Data!PD
A4: BUDGET | B4: 100000000 | C4: 80000000 | D4: 90000000 | E4: 95000000 | F4: 105000000 | G4: 110000000 | H4: 120000000 | I4: Copia a LP_Model!B2
A5: FICO_MIN | B5: 700 | C5: 700 | D5: 700 | E5: 710 | F5: 710 | G5: 720 | H5: 730 | I5: Pruebe umbrales
A6: DTI_MAX | B6: 0.35 | C6: 0.3 | D6: 0.32 | E6: 0.33 | F6: 0.37 | G6: 0.38 | H6: 0.4 | I6: Pruebe umbrales
A8: Resultado esperado (recalcule con Solver en cada columna)
A9: Métrica | B9: Base | C9: -20% | D9: -10% | E9: -5% | F9: +5% | G9: +10% | H9: +20%
A10: OBJ_RAR | B10: =LP_Model!B68
A11: Total_Asignado | B11: =LP_Model!B69
A12: Avg_FICO | B12: =LP_Model!B72
A13: Avg_DTI | B13: =LP_Model!B73

Sheet Binary_Model
A1: Modelo binario de crisis – variables y parámetros
A2: Descripción | B2: Valor | C2: Nota
A3: Presupuesto de mitigación (M) | B3: 5000000 | C3: Tope en gastos de medidas
A4: Costo por medida (por segmento) | B4: =ROUNDUP(0.002*LP_Model!B2,0) | C4: 2 bps del budget
A6: Segmento | B6: Región | C6: Propósito | D6: FICO_mid | E6: PD_base | F6: Impacto_PD_si_activa | G6: Costo | H6: z(0/1)
A7: seg_risk_1 | B7: Andina | C7: Vivienda | D7: 680 | E7: 0.045651409 | F7: -0.015 | G7: =BINARY_MODEL!$B$3 | H7: 0
A8: seg_risk_2 | B8: Pacífica | C8: Vivienda | D8: 680 | E8: 0.046029034 | F8: -0.015 | G8: =BINARY_MODEL!$B$3 | H8: 0
A9: seg_risk_3 | B9: Orinoquía | C9: Vivienda | D9: 680 | E9: 0.047139419 | F9: -0.015 | G9: =BINARY_MODEL!$B$3 | H9: 0
A10: seg_risk_4 | B10: Amazonía | C10: Vivienda | D10: 680 | E10: 0.049694417 | F10: -0.015 | G10: =BINARY_MODEL!$B$3 | H10: 0
A11: seg_risk_5 | B11: Andina | C11: Vivienda | D11: 720 | E11: 0.032959035 | F11: -0.015 | G11: =BINARY_MODEL!$B$3 | H11: 0
A12: seg_risk_6 | B12: Caribe | C12: Vivienda | D12: 680 | E12: 0.051446598 | F12: -0.015 | G12: =BINARY_MODEL!$B$3 | H12: 0
A13: seg_risk_7 | B13: Pacífica | C13: Vivienda | D13: 720 | E13: 0.036852379 | F13: -0.015 | G13: =BINARY_MODEL!$B$3 | H13: 0
A14: seg_risk_8 | B14: Pacífica | C14: Educación | D14: 680 | E14: 0.061704401 | F14: -0.015 | G14: =BINARY_MODEL!$B$3 | H14: 0
A15: seg_risk_9 | B15: Orinoquía | C15: Vivienda | D15: 720 | E15: 0.035605717 | F15: -0.015 | G15: =BINARY_MODEL!$B$3 | H15: 0
A16: seg_risk_10 | B16: Pacífica | C16: Vivienda | D16: 770 | E16: 0.025095143 | F16: -0.015 | G16: =BINARY_MODEL!$B$3 | H16: 0
A17: seg_risk_11 | B17: Andina | C17: Vivienda | D17: 770 | E17: 0.023722582 | F17: -0.015 | G17: =BINARY_MODEL!$B$3 | H17: 0
A18: seg_risk_12 | B18: Caribe | C18: Vivienda | D18: 720 | E18: 0.035587879 | F18: -0.015 | G18: =BINARY_MODEL!$B$3 | H18: 0
... A26: seg_risk_20 | B26: Pacífica | C26: Deuda | D26: 680 | E26: 0.088568246 | F26: -0.015 | G26: =BINARY_MODEL!$B$3 | H26: 0
A28: Objetivo (min mora ajustada) | B28: =SUMPRODUCT(E8:E27,1+F8:F27*H8:H27)
A29: Costo total medidas | B29: =SUMPRODUCT(G8:G27,H8:H27)
A30: Restricción de presupuesto (<= M) | B30: =BINARY_MODEL!B11
